Workbook

Sheet Resumo Contrato Reajustado 2026
A1: Cód. Item | B1: Item Contratual | C1: Quantidade Contratada | D1: Item | E1: Quantidade | F1: Preço Unitário | G1: Total | H1: Indice Reajuste | I1: Novo Unitário | J1: Total | K1: Indice Reajuste | L1: Novo Unitário | M1: Total | N1: Indice Reajuste | O1: Novo Unitário | P1: Total | Q1: Indice Reajuste | R1: Novo Unitário | S1: Total
A2: 1 | B2: Banner - Banner em lona com impressão digital de alta qualidade, medida 1,20m x 0,90m acabamento de madeira e ponta de PVC, com tripé. | C2: 75 | D2: 22899-0 | E2: 5 | F2: 75 | G2: =F2*E2 -> 375 | H2: 0.082 | I2: =$F2+$F2*$H2 -> 81.15 | J2: =I2*E2 -> 405.75 | K2: 0.0351 | L2: =I2+I2*K2 -> 83.998365 | M2: =L2*E2 -> 419.99183 | N2: 0.0345 | O2: =L2+L2*N2 -> 86.896309 | P2: =O2*E2 -> 434.48154 | Q2: 0.0541 | R2: =O2+O2*Q2 -> 91.597399 | S2: =R2*E2 -> 457.98699
A3: 2 | B3: Banner - Banner em lona com impressão digital de alta qualidade, medida 1,50m x 0,90m acabamento de madeira e ponta de PVC, com tripé. | C3: 75 | D3: 22900-8 | E3: 5 | F3: 85 | G3: =F3*E3 -> 425 | H3: 0.082 | I3: =$F3+$F3*$H3 -> 91.97 | J3: =I3*E3 -> 459.85 | K3: 0.0351 | L3: =I3+I3*K3 -> 95.198147 | M3: =L3*E3 -> 475.99074 | N3: 0.0345 | O3: =L3+L3*N3 -> 98.482483 | P3: =O3*E3 -> 492.41242 | Q3: 0.0541 | R3: =O3+O3*Q3 -> 103.81039 | S3: =R3*E3 -> 519.05193
A4: 3 | B4: Banner- Banner em lona com impressão digital de alta qualidade, medida 1,30X 1,80m acabamento de madeira e ponta de PVC, com tripé. | C4: 75 | D4: 22901-6 | E4: 5 | F4: 120 | G4: =F4*E4 -> 600 | H4: 0.082 | I4: =$F4+$F4*$H4 -> 129.84 | J4: =I4*E4 -> 649.2 | K4: 0.0351 | L4: =I4+I4*K4 -> 134.39738 | M4: =L4*E4 -> 671.98692 | N4: 0.0345 | O4: =L4+L4*N4 -> 139.03409 | P4: =O4*E4 -> 695.17047 | Q4: 0.0541 | R4: =O4+O4*Q4 -> 146.55584 | S4: =R4*E4 -> 732.77919
A5: 4 | B5: Cartão Cerimonial - Cartão cerimonial formato 12,5cm x 8,5cm, papel cartão supremo 330gr impressão 1 x 1 cores | C5: 3000 | D5: 23039-1 | E5: 200 | F5: 0.9 | G5: =F5*E5 -> 180 | H5: 0.082 | I5: =$F5+$F5*$H5 -> 0.9738 | J5: =I5*E5 -> 194.76 | K5: 0.0351 | L5: =I5+I5*K5 -> 1.0079804 | M5: =L5*E5 -> 201.59608 | N5: 0.0345 | O5: =L5+L5*N5 -> 1.0427557 | P5: =O5*E5 -> 208.55114 | Q5: 0.0541 | R5: =O5+O5*Q5 -> 1.0991688 | S5: =R5*E5 -> 219.83376
A6: 5 | B6: Cartão Cerimonial -Cartão cerimonial formato 12,5cm x 8,5cm, papel cartão supremo 330gr impressão 4 x 0 cores | C6: 3000 | D6: 23040-5 | E6: 200 | F6: 0.9 | G6: =F6*E6 -> 180 | H6: 0.082 | I6: =$F6+$F6*$H6 -> 0.9738 | J6: =I6*E6 -> 194.76 | K6: 0.0351 | L6: =I6+I6*K6 -> 1.0079804 | M6: =L6*E6 -> 201.59608 | N6: 0.0345 | O6: =L6+L6*N6 -> 1.0427557 | P6: =O6*E6 -> 208.55114 | Q6: 0.0541 | R6: =O6+O6*Q6 -> 1.0991688 | S6: =R6*E6 -> 219.83376
A7: 6 | B7: Cartão de visita - Cartão de visita formato 9,5cm x 5,5cm, acabamento refile. | C7: 4500 | D7: 22935-0 | E7: 300 | F7: 0.12 | G7: =F7*E7 -> 36 | H7: 0.082 | I7: =$F7+$F7*$H7 -> 0.12984 | J7: =I7*E7 -> 38.952 | K7: 0.0351 | L7: =I7+I7*K7 -> 0.13439738 | M7: =L7*E7 -> 40.319215 | N7: 0.0345 | O7: =L7+L7*N7 -> 0.13903409 | P7: =O7*E7 -> 41.710228 | Q7: 0.0541 | R7: =O7+O7*Q7 -> 0.14655584 | S7: =R7*E7 -> 43.966751
A8: 7 | B8: Cartão de visita - EM BRAILEARTE/MATRIZES ,TRADUÇÃO E REVISÃO ORTOGRÁFICA EM BRAILE POR CONTA DA CONTRATADA Cartão de 9,5cm(L) x 5,5cm(A); papel duplex 300gr ou cartão, impressão 4X0 cores, gravação braile na frente. | C8: 1500 | D8: 22936-9 | E8: 100 | F8: 2 | G8: =F8*E8 -> 200 | H8: 0.082 | I8: =$F8+$F8*$H8 -> 2.164 | J8: =I8*E8 -> 216.4 | K8: 0.0351 | L8: =I8+I8*K8 -> 2.2399564 | M8: =L8*E8 -> 223.99564 | N8: 0.0345 | O8: =L8+L8*N8 -> 2.3172349 | P8: =O8*E8 -> 231.72349 | Q8: 0.0541 | R8: =O8+O8*Q8 -> 2.4425973 | S8: =R8*E8 -> 244.25973
A9: 8 | B9: Cartaz -Cartaz formato 60cm x 40cm, papel couche 150gr, impressão 4 x 0 cores, acabamento dupla face e refile | C9: 75 | D9: 22950-4 | E9: 5 | F9: 12 | G9: =F9*E9 -> 60 | H9: 0.082 | I9: =$F9+$F9*$H9 -> 12.984 | J9: =I9*E9 -> 64.92 | K9: 0.0351 | L9: =I9+I9*K9 -> 13.439738 | M9: =L9*E9 -> 67.198692 | N9: 0.0345 | O9: =L9+L9*N9 -> 13.903409 | P9: =O9*E9 -> 69.517047 | Q9: 0.0541 | R9: =O9+O9*Q9 -> 14.655584 | S9: =R9*E9 -> 73.277919
A10: 9 | B10: Cartilha- Cartilha formato 29,7cm x 21cm, A4 fechado, 96 páginas, papel couche 115gr, impressão 4 x 4 cores, acabamento hotmelt | C10: 3000 | D10: 22973-3 | E10: 200 | F10: 14 | G10: =F10*E10 -> 2800 | H10: 0.082 | I10: =$F10+$F10*$H10 -> 15.148 | J10: =I10*E10 -> 3029.6 | K10: 0.0351 | L10: =I10+I10*K10 -> 15.679695 | M10: =L10*E10 -> 3135.939 | N10: 0.0345 | O10: =L10+L10*N10 -> 16.220644 | P10: =O10*E10 -> 3244.1289 | Q10: 0.0541 | R10: =O10+O10*Q10 -> 17.098181 | S10: =R10*E10 -> 3419.6362
A11: 10 | B11: Cartilha/ book -Cartilha formato 29,7cm x 21cm, 96 páginas, papel couche 115gr, impressão 4 x 4 cores, capa dura | C11: 3000 | D11: 22974-1 | E11: 200 | F11: 16 | G11: =F11*E11 -> 3200 | H11: 0.082 | I11: =$F11+$F11*$H11 -> 17.312 | J11: =I11*E11 -> 3462.4 | K11: 0.0351 | L11: =I11+I11*K11 -> 17.919651 | M11: =L11*E11 -> 3583.9302 | N11: 0.0345 | O11: =L11+L11*N11 -> 18.537879 | P11: =O11*E11 -> 3707.5758 | Q11: 0.0541 | R11: =O11+O11*Q11 -> 19.540778 | S11: =R11*E11 -> 3908.1557
A12: 11 | B12: Certificado - Certificado formato 21cm x 29,7 - A4, papel couche brilho 300gr, impressão 4 x 0 cores, acabamento refile | C12: 3000 | D12: 22975-0 | E12: 200 | F12: 0.9 | G12: =F12*E12 -> 180 | H12: 0.082 | I12: =$F12+$F12*$H12 -> 0.9738 | J12: =I12*E12 -> 194.76 | K12: 0.0351 | L12: =I12+I12*K12 -> 1.0079804 | M12: =L12*E12 -> 201.59608 | N12: 0.0345 | O12: =L12+L12*N12 -> 1.0427557 | P12: =O12*E12 -> 208.55114 | Q12: 0.0541 | R12: =O12+O12*Q12 -> 1.0991688 | S12: =R12*E12 -> 219.83376
A13: 12 | B13: Convite - Convite formato 17cm x 9cm, papel couche brilho 170gr, numerado impressão 4 x 0 cores, acabamento refile | C13: 1500 | D13: 22976-8 | E13: 100 | F13: 1.39 | G13: =F13*E13 -> 139 | H13: 0.082 | I13: =$F13+$F13*$H13 -> 1.50398 | J13: =I13*E13 -> 150.398 | K13: 0.0351 | L13: =I13+I13*K13 -> 1.5567697 | M13: =L13*E13 -> 155.67697 | N13: 0.0345 | O13: =L13+L13*N13 -> 1.6104783 | P13: =O13*E13 -> 161.04783 | Q13: 0.0541 | R13: =O13+O13*Q13 -> 1.6976051 | S13: =R13*E13 -> 169.76051
... A43: 42 | B43: Serviço de impressão/plotagem colorida de Projetos de Engenharia incluso dobragem conforme ABNT/NBR 13142/1999, formatos série ABNT A2. Impressão a laser ou tinta térmica em papel sulfite branco, gramatura mínima 75g/m2, resolução de impressão igual ou superior a 1200dpi x 1200 dpi (ponto por polegada quadrada), a partir de arquivos digitais a serem fornecidos pela CONTRATANTE | C43: 450 | D43: 23047-2 | E43: 30 | F43: 7.88 | G43: =F43*E43 -> 236.4 | H43: 0.082 | I43: =$F43+$F43*$H43 -> 8.52616 | J43: =I43*E43 -> 255.7848 | K43: 0.0351 | L43: =I43+I43*K43 -> 8.8254282 | M43: =L43*E43 -> 264.76285 | N43: 0.0345 | O43: =L43+L43*N43 -> 9.1299055 | P43: =O43*E43 -> 273.89716 | Q43: 0.0541 | R43: =O43+O43*Q43 -> 9.6238334 | S43: =R43*E43 -> 288.715
A48: 1
A49: 2
A50: 3
A51: 4
A52: 5
A53: 6
A54: 7
A55: 8
A56: 9
A57: 10
A58: 11
A59: 12
... A89: 42

Sheet Janeiro
A1: Data | B1: Nome Solicitante | C1: Setor Responsável | D1: Pedido | E1: Quantidade | F1: Item | G1: Valor Unitário | H1: Valor do Pedido | J1: Controle de Utilização Mensal
A2: 46023 | B2: Gustavo | C2: DIPES | D2: 2 Banner 1,90x1,20 | E2: 158 | F2: 4 | G2: =IF(F2="","",VLOOKUP(F2,'Resumo Contrato Reajustado 2026'!$A$2:$S$43,18,0)) -> 1.0991688 | H2: =IF(F2="","",E2*G2) -> 173.66867 | J2: Item | K2: Quantidade Utilizada | L2: Quantidade Mensal | M2: Total | O2: Valor a Pagar | P2: =SUM(H2:H46) -> 19590.546
A3: 46023 | B3: Humberto | C3: CONVIVA | D3: A4 sulfite, Frente Colorido | E3: 126 | F3: 9 | G3: =IF(F3="","",VLOOKUP(F3,'Resumo Contrato Reajustado 2026'!$A$2:$S$43,18,0)) -> 17.098181 | H3: =IF(F3="","",E3*G3) -> 2154.3708 | J3: 1 | K3: =SUMIF($F$2:$F$46,J3,$E$2:$E$46) -> 0 | L3: 5 | M3: =L3-K3 -> 5
A4: 46023 | B4: Humberto | C4: CONVIVA | D4: 04 Banners 180x130 | E4: 293 | F4: 15 | G4: =IF(F4="","",VLOOKUP(F4,'Resumo Contrato Reajustado 2026'!$A$2:$S$43,18,0)) -> 1.3434285 | H4: =IF(F4="","",E4*G4) -> 393.62456 | J4: 2 | K4: =SUMIF($F$2:$F$46,J4,$E$2:$E$46) -> 0 | L4: 5 | M4: =L4-K4 -> 5
A5: 46023 | B5: Maria Carolina | C5: CERIMONIAL | D5: 1000 A5 180 grs | E5: 186 | F5: 16 | G5: =IF(F5="","",VLOOKUP(F5,'Resumo Contrato Reajustado 2026'!$A$2:$S$43,18,0)) -> 13.434285 | H5: =IF(F5="","",E5*G5) -> 2498.777 | J5: 3 | K5: =SUMIF($F$2:$F$46,J5,$E$2:$E$46) -> 0 | L5: 5 | M5: =L5-K5 -> 5
A6: 46023 | B6: Maria Carolina | C6: CERIMONIAL | D6: 3000 Fichas 14x9 180 grs | E6: 15847 | F6: 21 | G6: =IF(F6="","",VLOOKUP(F6,'Resumo Contrato Reajustado 2026'!$A$2:$S$43,18,0)) -> 0.37860258 | H6: =IF(F6="","",E6*G6) -> 5999.7151 | J6: 4 | K6: =SUMIF($F$2:$F$46,J6,$E$2:$E$46) -> 158 | L6: 200 | M6: =L6-K6 -> 42
A7: 46023 | B7: Caroline | C7: SUCOR | D7: 16 Revistas | E7: 5427 | F7: 25 | G7: =IF(F7="","",VLOOKUP(F7,'Resumo Contrato Reajustado 2026'!$A$2:$S$43,18,0)) -> 0.85490906 | H7: =IF(F7="","",E7*G7) -> 4639.5914 | J7: 5 | K7: =SUMIF($F$2:$F$46,J7,$E$2:$E$46) -> 0 | L7: 200 | M7: =L7-K7 -> 200
A8: 46023 | B8: Amanda | C8: EFAPE | D8: 2 Banners 90x1,20 | E8: 158 | F8: 11 | G8: =IF(F8="","",VLOOKUP(F8,'Resumo Contrato Reajustado 2026'!$A$2:$S$43,18,0)) -> 1.0991688 | H8: =IF(F8="","",E8*G8) -> 173.66867 | J8: 6 | K8: =SUMIF($F$2:$F$46,J8,$E$2:$E$46) -> 0 | L8: 300 | M8: =L8-K8 -> 300
A9: 46023 | B9: Amanda | C9: EFAPE | D9: 6 A4 sulfite e plastificado | E9: 272 | F9: 27 | G9: =IF(F9="","",VLOOKUP(F9,'Resumo Contrato Reajustado 2026'!$A$2:$S$43,18,0)) -> 0.29311168 | H9: =IF(F9="","",E9*G9) -> 79.726376 | J9: 7 | K9: =SUMIF($F$2:$F$46,J9,$E$2:$E$46) -> 0 | L9: 100 | M9: =L9-K9 -> 100
A10: 46023 | B10: Amanda | C10: EFAPE | D10: 55 A4 F/V 180 grs | E10: 257 | F10: 30 | G10: =IF(F10="","",VLOOKUP(F10,'Resumo Contrato Reajustado 2026'!$A$2:$S$43,18,0)) -> 3.2242284 | H10: =IF(F10="","",E10*G10) -> 828.62671 | J10: 8 | K10: =SUMIF($F$2:$F$46,J10,$E$2:$E$46) -> 0 | L10: 5 | M10: =L10-K10 -> 5
A11: 46023 | B11: Amanda | C11: EFAPE | D11: 6 A2 210 grs | E11: 180 | F11: 31 | G11: =IF(F11="","",VLOOKUP(F11,'Resumo Contrato Reajustado 2026'!$A$2:$S$43,18,0)) -> 3.663896 | H11: =IF(F11="","",E11*G11) -> 659.50127 | J11: 9 | K11: =SUMIF($F$2:$F$46,J11,$E$2:$E$46) -> 126 | L11: 200 | M11: =L11-K11 -> 74
A12: 46023 | B12: Amanda | C12: EFAPE | D12: 78 Impressão A3 | E12: 194 | F12: 32 | G12: =IF(F12="","",VLOOKUP(F12,'Resumo Contrato Reajustado 2026'!$A$2:$S$43,18,0)) -> 3.663896 | H12: =IF(F12="","",E12*G12) -> 710.79582 | J12: 10 | K12: =SUMIF($F$2:$F$46,J12,$E$2:$E$46) -> 0 | L12: 200 | M12: =L12-K12 -> 200
A13: 46023 | B13: Heloisa | C13: SUPED | D13: 06 Mapas | E13: 2333 | F13: 36 | G13: =IF(F13="","",VLOOKUP(F13,'Resumo Contrato Reajustado 2026'!$A$2:$S$43,18,0)) -> 0.48851946 | H13: =IF(F13="","",E13*G13) -> 1139.7159 | J13: 11 | K13: =SUMIF($F$2:$F$46,J13,$E$2:$E$46) -> 158 | L13: 200 | M13: =L13-K13 -> 42
A14: 46023 | B14: Tamires | C14: DIISE | D14: Banner 1,50x1,50 | E14: 299 | F14: 37 | G14: =IF(F14="","",VLOOKUP(F14,'Resumo Contrato Reajustado 2026'!$A$2:$S$43,18,0)) -> 0.46409349 | H14: =IF(F14="","",E14*G14) -> 138.76395 | J14: 12 | K14: =SUMIF($F$2:$F$46,J14,$E$2:$E$46) -> 0 | L14: 100 | M14: =L14-K14 -> 100
G15: =IF(F15="","",VLOOKUP(F15,'Resumo Contrato Reajustado 2026'!$A$2:$S$43,18,0)) | H15: =IF(F15="","",E15*G15) | J15: 13 | K15: =SUMIF($F$2:$F$46,J15,$E$2:$E$46) -> 0 | L15: 200 | M15: =L15-K15 -> 200
G16: =IF(F16="","",VLOOKUP(F16,'Resumo Contrato Reajustado 2026'!$A$2:$S$43,18,0)) | H16: =IF(F16="","",E16*G16) | J16: 14 | K16: =SUMIF($F$2:$F$46,J16,$E$2:$E$46) -> 0 | L16: 200 | M16: =L16-K16 -> 200
G17: =IF(F17="","",VLOOKUP(F17,'Resumo Contrato Reajustado 2026'!$A$2:$S$43,18,0)) | H17: =IF(F17="","",E17*G17) | J17: 15 | K17: =SUMIF($F$2:$F$46,J17,$E$2:$E$46) -> 293 | L17: 300 | M17: =L17-K17 -> 7
G18: =IF(F18="","",VLOOKUP(F18,'Resumo Contrato Reajustado 2026'!$A$2:$S$43,18,0)) | H18: =IF(F18="","",E18*G18) | J18: 16 | K18: =SUMIF($F$2:$F$46,J18,$E$2:$E$46) -> 186 | L18: 200 | M18: =L18-K18 -> 14
G19: =IF(F19="","",VLOOKUP(F19,'Resumo Contrato Reajustado 2026'!$A$2:$S$43,18,0)) | H19: =IF(F19="","",E19*G19) | J19: 17 | K19: =SUMIF($F$2:$F$46,J19,$E$2:$E$46) -> 0 | L19: 200 | M19: =L19-K19 -> 200
G20: =IF(F20="","",VLOOKUP(F20,'Resumo Contrato Reajustado 2026'!$A$2:$S$43,18,0)) | H20: =IF(F20="","",E20*G20) | J20: 18 | K20: =SUMIF($F$2:$F$46,J20,$E$2:$E$46) -> 0 | L20: 500 | M20: =L20-K20 -> 500
G21: =IF(F21="","",VLOOKUP(F21,'Resumo Contrato Reajustado 2026'!$A$2:$S$43,18,0)) | J21: 19 | K21: =SUMIF($F$2:$F$46,J21,$E$2:$E$46) -> 0 | L21: 80000 | M21: =L21-K21 -> 80000
G22: =IF(F22="","",VLOOKUP(F22,'Resumo Contrato Reajustado 2026'!$A$2:$S$43,18,0)) | J22: 20 | K22: =SUMIF($F$2:$F$46,J22,$E$2:$E$46) -> 0 | L22: 500 | M22: =L22-K22 -> 500
G23: =IF(F23="","",VLOOKUP(F23,'Resumo Contrato Reajustado 2026'!$A$2:$S$43,18,0)) | J23: 21 | K23: =SUMIF($F$2:$F$46,J23,$E$2:$E$46) -> 15847 | L23: 50000 | M23: =L23-K23 -> 34153
G24: =IF(F24="","",VLOOKUP(F24,'Resumo Contrato Reajustado 2026'!$A$2:$S$43,18,0)) | J24: 22 | K24: =SUMIF($F$2:$F$46,J24,$E$2:$E$46) -> 0 | L24: 500 | M24: =L24-K24 -> 500
G25: =IF(F25="","",VLOOKUP(F25,'Resumo Contrato Reajustado 2026'!$A$2:$S$43,18,0)) | J25: 23 | K25: =SUMIF($F$2:$F$46,J25,$E$2:$E$46) -> 0 | L25: 80000 | M25: =L25-K25 -> 80000
G26: =IF(F26="","",VLOOKUP(F26,'Resumo Contrato Reajustado 2026'!$A$2:$S$43,18,0)) | J26: 24 | K26: =SUMIF($F$2:$F$46,J26,$E$2:$E$46) -> 0 | L26: 500 | M26: =L26-K26 -> 500
G27: =IF(F27="","",VLOOKUP(F27,'Resumo Contrato Reajustado 2026'!$A$2:$S$43,18,0)) | J27: 25 | K27: =SUMIF($F$2:$F$46,J27,$E$2:$E$46) -> 5427 | L27: 50000 | M27: =L27-K27 -> 44573
G28: =IF(F28="","",VLOOKUP(F28,'Resumo Contrato Reajustado 2026'!$A$2:$S$43,18,0)) | J28: 26 | K28: =SUMIF($F$2:$F$46,J28,$E$2:$E$46) -> 0 | L28: 300 | M28: =L28-K28 -> 300
G29: =IF(F29="","",VLOOKUP(F29,'Resumo Contrato Reajustado 2026'!$A$2:$S$43,18,0)) | H29: =IF(F29="","",E29*G29) | J29: 27 | K29: =SUMIF($F$2:$F$46,J29,$E$2:$E$46) -> 272 | L29: 300 | M29: =L29-K29 -> 28
G30: =IF(F30="","",VLOOKUP(F30,'Resumo Contrato Reajustado 2026'!$A$2:$S$43,18,0)) | J30: 28 | K30: =SUMIF($F$2:$F$46,J30,$E$2:$E$46) -> 0 | L30: 300 | M30: =L30-K30 -> 300
G31: =IF(F31="","",VLOOKUP(F31,'Resumo Contrato Reajustado 2026'!$A$2:$S$43,18,0)) | J31: 29 | K31: =SUMIF($F$2:$F$46,J31,$E$2:$E$46) -> 0 | L31: 300 | M31: =L31-K31 -> 300
G32: =IF(F32="","",VLOOKUP(F32,'Resumo Contrato Reajustado 2026'!$A$2:$S$43,18,0)) | J32: 30 | K32: =SUMIF($F$2:$F$46,J32,$E$2:$E$46) -> 257 | L32: 300 | M32: =L32-K32 -> 43
G33: =IF(F33="","",VLOOKUP(F33,'Resumo Contrato Reajustado 2026'!$A$2:$S$43,18,0)) | J33: 31 | K33: =SUMIF($F$2:$F$46,J33,$E$2:$E$46) -> 180 | L33: 300 | M33: =L33-K33 -> 120
B34: Amanda | D34: 6 Impressão A3 | E34: =6 -> 6 | J34: 32 | K34: =SUMIF($F$2:$F$46,J34,$E$2:$E$46) -> 194 | L34: 300 | M34: =L34-K34 -> 106
G35: =IF(F35="","",VLOOKUP(F35,'Resumo Contrato Reajustado 2026'!$A$2:$S$43,18,0)) | J35: 33 | K35: =SUMIF($F$2:$F$46,J35,$E$2:$E$46) -> 0 | L35: 200 | M35: =L35-K35 -> 200
G36: =IF(F36="","",VLOOKUP(F36,'Resumo Contrato Reajustado 2026'!$A$2:$S$43,18,0)) | J36: 34 | K36: =SUMIF($F$2:$F$46,J36,$E$2:$E$46) -> 0 | L36: 200 | M36: =L36-K36 -> 200
G37: =IF(F37="","",VLOOKUP(F37,'Resumo Contrato Reajustado 2026'!$A$2:$S$43,18,0)) | J37: 35 | K37: =SUMIF($F$2:$F$46,J37,$E$2:$E$46) -> 0 | L37: 200 | M37: =L37-K37 -> 200
G38: =IF(F38="","",VLOOKUP(F38,'Resumo Contrato Reajustado 2026'!$A$2:$S$43,18,0)) | J38: 36 | K38: =SUMIF($F$2:$F$46,J38,$E$2:$E$46) -> 2333 | L38: 5000 | M38: =L38-K38 -> 2667
G39: =IF(F39="","",VLOOKUP(F39,'Resumo Contrato Reajustado 2026'!$A$2:$S$43,18,0)) | J39: 37 | K39: =SUMIF($F$2:$F$46,J39,$E$2:$E$46) -> 299 | L39: 300 | M39: =L39-K39 -> 1
G40: =IF(F40="","",VLOOKUP(F40,'Resumo Contrato Reajustado 2026'!$A$2:$S$43,18,0)) | J40: 38 | K40: =SUMIF($F$2:$F$46,J40,$E$2:$E$46) -> 0 | L40: 300 | M40: =L40-K40 -> 300
...

Sheet Fevereiro
A1: Data | B1: Nome Solicitante | C1: Setor Responsável | D1: Pedido | E1: Quantidade | F1: Item | G1: Valor Unitário | H1: Valor do Pedido | J1: Controle de Utilização Mensal
A2: 46054 | B2: Jeniffer | C2: EFAPE | D2: Guia Pratico F/V colorido | E2: 243 | F2: 15 | G2: =IF(F2="","",VLOOKUP(F2,'Resumo Contrato Reajustado 2026'!$A$2:$S$43,18,0)) -> 1.3434285 | H2: =IF(F2="","",E2*G2) -> 326.45313 | J2: Item | K2: Quantidade Utilizada | L2: Quantidade Mensal | M2: Total | O2: Valor a Pagar | P2: =SUM(H2:H46) -> 82020.353
A3: 46054 | B3: Jeniffer | C3: EFAPE | D3: Carta Obstaculo | E3: 5 | F3: 2 | G3: =IF(F3="","",VLOOKUP(F3,'Resumo Contrato Reajustado 2026'!$A$2:$S$43,18,0)) -> 103.81039 | H3: =IF(F3="","",E3*G3) -> 519.05193 | J3: 1 | K3: =SUMIF($F$2:$F$46,J3,$E$2:$E$46) -> 0 | L3: 5 | M3: =L3-K3 -> 5
A4: 46054 | B4: Jeniffer | C4: EFAPE | D4: Painel Tsuru dourado P. Fot. ColorA2 | E4: 200 | F4: 4 | G4: =IF(F4="","",VLOOKUP(F4,'Resumo Contrato Reajustado 2026'!$A$2:$S$43,18,0)) -> 1.0991688 | H4: =IF(F4="","",E4*G4) -> 219.83376 | J4: 2 | K4: =SUMIF($F$2:$F$46,J4,$E$2:$E$46) -> 5 | L4: 5 | M4: =L4-K4 -> 0
A5: 46054 | B5: Jeniffer | C5: EFAPE | D5: Banner 115x55 | E5: 166 | F5: 5 | G5: =IF(F5="","",VLOOKUP(F5,'Resumo Contrato Reajustado 2026'!$A$2:$S$43,18,0)) -> 1.0991688 | H5: =IF(F5="","",E5*G5) -> 182.46202 | J5: 3 | K5: =SUMIF($F$2:$F$46,J5,$E$2:$E$46) -> 0 | L5: 5 | M5: =L5-K5 -> 5
A6: 46054 | B6: Jeniffer | C6: EFAPE | D6: Banner 115x45 | E6: 83 | F6: 11 | G6: =IF(F6="","",VLOOKUP(F6,'Resumo Contrato Reajustado 2026'!$A$2:$S$43,18,0)) -> 1.0991688 | H6: =IF(F6="","",E6*G6) -> 91.231009 | J6: 4 | K6: =SUMIF($F$2:$F$46,J6,$E$2:$E$46) -> 200 | L6: 200 | M6: =L6-K6 -> 0
A7: 46054 | B7: Jeniffer | C7: EFAPE | D7: Folha Rotas de Mestre | E7: 7779 | F7: 19 | G7: =IF(F7="","",VLOOKUP(F7,'Resumo Contrato Reajustado 2026'!$A$2:$S$43,18,0)) -> 0.097703892 | H7: =IF(F7="","",E7*G7) -> 760.03858 | J7: 5 | K7: =SUMIF($F$2:$F$46,J7,$E$2:$E$46) -> 166 | L7: 200 | M7: =L7-K7 -> 34
A8: 46054 | B8: Jeniffer | C8: EFAPE | D8: Rota do Tesouro P/B F/V A4 | E8: 13 | F8: 19 | G8: =IF(F8="","",VLOOKUP(F8,'Resumo Contrato Reajustado 2026'!$A$2:$S$43,18,0)) -> 0.097703892 | H8: =IF(F8="","",E8*G8) -> 1.2701506 | J8: 6 | K8: =SUMIF($F$2:$F$46,J8,$E$2:$E$46) -> 0 | L8: 300 | M8: =L8-K8 -> 300
A9: 46054 | B9: Jeniffer | C9: EFAPE | D9: Cartas normativas A4 colorido | E9: 39 | F9: 19 | G9: =IF(F9="","",VLOOKUP(F9,'Resumo Contrato Reajustado 2026'!$A$2:$S$43,18,0)) -> 0.097703892 | H9: =IF(F9="","",E9*G9) -> 3.8104518 | J9: 7 | K9: =SUMIF($F$2:$F$46,J9,$E$2:$E$46) -> 0 | L9: 100 | M9: =L9-K9 -> 100
A10: 46054 | B10: Jeniffer | C10: EFAPE | D10: Arquivo Teams Game | E10: 365 | F10: 20 | G10: =IF(F10="","",VLOOKUP(F10,'Resumo Contrato Reajustado 2026'!$A$2:$S$43,18,0)) -> 1.2212987 | H10: =IF(F10="","",E10*G10) -> 445.77401 | J10: 8 | K10: =SUMIF($F$2:$F$46,J10,$E$2:$E$46) -> 0 | L10: 5 | M10: =L10-K10 -> 5
A11: 46054 | B11: Jeniffer | C11: EFAPE | D11: Banner Oficina Seminario 90x1,20 | E11: 21533 | F11: 21 | G11: =IF(F11="","",VLOOKUP(F11,'Resumo Contrato Reajustado 2026'!$A$2:$S$43,18,0)) -> 0.37860258 | H11: =IF(F11="","",E11*G11) -> 8152.4494 | J11: 9 | K11: =SUMIF($F$2:$F$46,J11,$E$2:$E$46) -> 0 | L11: 200 | M11: =L11-K11 -> 200
A12: 46054 | B12: Jeniffer | C12: EFAPE | D12: A6, F/V, color, firme | E12: 4000 | F12: 21 | G12: =IF(F12="","",VLOOKUP(F12,'Resumo Contrato Reajustado 2026'!$A$2:$S$43,18,0)) -> 0.37860258 | H12: =IF(F12="","",E12*G12) -> 1514.4103 | J12: 10 | K12: =SUMIF($F$2:$F$46,J12,$E$2:$E$46) -> 0 | L12: 200 | M12: =L12-K12 -> 200
A13: 46054 | B13: Jeniffer | C13: EFAPE | D13: Banner 115x130 | E13: 500 | F13: 22 | G13: =IF(F13="","",VLOOKUP(F13,'Resumo Contrato Reajustado 2026'!$A$2:$S$43,18,0)) -> 0.58622335 | H13: =IF(F13="","",E13*G13) -> 293.11168 | J13: 11 | K13: =SUMIF($F$2:$F$46,J13,$E$2:$E$46) -> 83 | L13: 200 | M13: =L13-K13 -> 117
A14: 46054 | B14: Jeniffer | C14: EFAPE | D14: Selos Tsuru Adesivos | E14: 64020 | F14: 23 | G14: =IF(F14="","",VLOOKUP(F14,'Resumo Contrato Reajustado 2026'!$A$2:$S$43,18,0)) -> 0.13434285 | H14: =IF(F14="","",E14*G14) -> 8600.6294 | J14: 12 | K14: =SUMIF($F$2:$F$46,J14,$E$2:$E$46) -> 0 | L14: 100 | M14: =L14-K14 -> 100
... A33: 46054 | B33: Luanna | C33: DIPES | D33: 2400 impressões A5 F/V color | E33: 2916 | F33: 21 | G33: =IF(F33="","",VLOOKUP(F33,'Resumo Contrato Reajustado 2026'!$A$2:$S$43,18,0)) -> 0.37860258 | H33: =IF(F33="","",E33*G33) -> 1104.0051 | J33: 31 | K33: =SUMIF($F$2:$F$46,J33,$E$2:$E$46) -> 207 | L33: 300 | M33: =L33-K33 -> 93
A34: 46054 | B34: Warley | C34: DPGDOC | D34: Saldo remanecente | E34: 41900 | F34: 25 | G34: =IF(F34="","",VLOOKUP(F34,'Resumo Contrato Reajustado 2026'!$A$2:$S$43,18,0)) -> 0.85490906 | H34: =IF(F34="","",E34*G34) -> 35820.689 | J34: 32 | K34: =SUMIF($F$2:$F$46,J34,$E$2:$E$46) -> 240 | L34: 300 | M34: =L34-K34 -> 60 | R34: =P34-Q34 -> 0
A35: 46054 | B35: Warley | C35: DPGDOC | D35: Saldo remanecente | E35: 20000 | F35: 21 | G35: =IF(F35="","",VLOOKUP(F35,'Resumo Contrato Reajustado 2026'!$A$2:$S$43,18,0)) -> 0.37860258 | H35: =IF(F35="","",E35*G35) -> 7572.0516 | J35: 33 | K35: =SUMIF($F$2:$F$46,J35,$E$2:$E$46) -> 0 | L35: 200 | M35: =L35-K35 -> 200
J36: 34 | K36: =SUMIF($F$2:$F$46,J36,$E$2:$E$46) -> 112 | L36: 200 | M36: =L36-K36 -> 88 | R36: =P36-Q36 -> 0
J37: 35 | K37: =SUMIF($F$2:$F$46,J37,$E$2:$E$46) -> 145 | L37: 200 | M37: =L37-K37 -> 55 | R37: =P37-Q37 -> 0
J38: 36 | K38: =SUMIF($F$2:$F$46,J38,$E$2:$E$46) -> 4625 | L38: 5000 | M38: =L38-K38 -> 375 | R38: =P38-Q38 -> 0
J39: 37 | K39: =SUMIF($F$2:$F$46,J39,$E$2:$E$46) -> 223 | L39: 300 | M39: =L39-K39 -> 77
J40: 38 | K40: =SUMIF($F$2:$F$46,J40,$E$2:$E$46) -> 296 | L40: 300 | M40: =L40-K40 -> 4
J41: 39 | K41: =SUMIF($F$2:$F$46,J41,$E$2:$E$46) -> 18 | L41: 30 | M41: =L41-K41 -> 12
J42: 40 | K42: =SUMIF($F$2:$F$46,J42,$E$2:$E$46) -> 13 | L42: 30 | M42: =L42-K42 -> 17
B43: Fatima | D43: 01 cento cartão visita F/V | G43: =IF(F43="","",VLOOKUP(F43,'Resumo Contrato Reajustado 2026'!$A$2:$S$43,18,0)) | H43: =IF(F43="","",E43*G43) | J43: 41 | K43: =SUMIF($F$2:$F$46,J43,$E$2:$E$46) -> 27 | L43: 30 | M43: =L43-K43 -> 3
B44: Fatima | D44: 1 certificado | G44: =IF(F44="","",VLOOKUP(F44,'Resumo Contrato Reajustado 2026'!$A$2:$S$43,18,0)) | H44: =IF(F44="","",E44*G44) | J44: 42 | K44: =SUMIF($F$2:$F$46,J44,$E$2:$E$46) -> 0 | L44: 30 | M44: =L44-K44 -> 30
I50: =SUM(I2:I48) -> 0

Sheet Março
A1: Data | B1: Nome Solicitante | C1: Setor Responsável | D1: Pedido | E1: Quantidade | F1: Item | G1: Valor Unitário | H1: Valor do Pedido | J1: Controle de Utilização Mensal
B2: Jeniffer | D2: Oficina 3 A4 Frente colorido | E2: 70 | G2: =IF(F2="","",VLOOKUP(F2,'Resumo Contrato Reajustado 2026'!$A$2:$S$43,18,0)) | H2: =IF(F2="","",E2*G2) | I2: ok | J2: Item | K2: Quantidade Utilizada | L2: Quantidade Mensal | M2: Total | O2: Valor a Pagar | P2: =SUM(H2:H40) -> 0
B3: Jeniffer | D3: Lembrancinha A4 Fot/adesivo | E3: 10 | G3: =IF(F3="","",VLOOKUP(F3,'Resumo Contrato Reajustado 2026'!$A$2:$S$43,18,0)) | H3: =IF(F3="","",E3*G3) | J3: 1 | K3: =SUMIF($F$2:$F$40,J3,$E$2:$E$40) -> 0 | L3: 5 | M3: =L3-K3 -> 5
A4: 3 | B4: Jeniffer | D4: Oficina 3 A4 Frente color 90 grs | E4: =16*6 -> 96 | I4: ok | J4: 2 | K4: =SUMIF($F$2:$F$40,J4,$E$2:$E$40) -> 0 | L4: 5 | M4: =L4-K4 -> 5
A5: 2a | B5: Jeniffer | D5: Escopo A4 Frente Color | E5: =70*2 -> 140 | I5: ok | J5: 3 | K5: =SUMIF($F$2:$F$40,J5,$E$2:$E$40) -> 0 | L5: 5 | M5: =L5-K5 -> 5
A6: 2a | B6: Jeniffer | D6: Escopo A4 Frente Color | E6: =70*2 -> 140 | I6: ok | J6: 4 | K6: =SUMIF($F$2:$F$40,J6,$E$2:$E$40) -> 0 | L6: 200 | M6: =L6-K6 -> 200
A7: 2b | B7: Jeniffer | D7: Oficina 2 A4 F/V Color | E7: =70*2 -> 140 | I7: ok | J7: 5 | K7: =SUMIF($F$2:$F$40,J7,$E$2:$E$40) -> 0 | L7: 200 | M7: =L7-K7 -> 200
B8: Jeniffer | D8: Oficina 1 A4 Frente Color | E8: =70*1 -> 70 | J8: 6 | K8: =SUMIF($F$2:$F$40,J8,$E$2:$E$40) -> 0 | L8: 300 | M8: =L8-K8 -> 300
A9: 4 | B9: Jeniffer | D9: 5590 Cartazes | I9: ok | J9: 7 | K9: =SUMIF($F$2:$F$40,J9,$E$2:$E$40) -> 0 | L9: 100 | M9: =L9-K9 -> 100
A10: 5 | B10: Jeniffer | D10: Leitura inicial A4 Frente Color | E10: =1*24 -> 24 | I10: ok | J10: 8 | K10: =SUMIF($F$2:$F$40,J10,$E$2:$E$40) -> 0 | L10: 5 | M10: =L10-K10 -> 5
A11: 5 | B11: Jeniffer | D11: Estudo de caso A4 Frente Color | E11: =24*2 -> 48 | I11: ok | J11: 9 | K11: =SUMIF($F$2:$F$40,J11,$E$2:$E$40) -> 0 | L11: 200 | M11: =L11-K11 -> 200
A12: 5 | B12: Jeniffer | D12: Tabela A4 Frente Color | E12: =24*6 -> 144 | I12: ok | J12: 10 | K12: =SUMIF($F$2:$F$40,J12,$E$2:$E$40) -> 0 | L12: 200 | M12: =L12-K12 -> 200
B13: Elaine | D13: 250 F/V P/B encadernação | J13: 11 | K13: =SUMIF($F$2:$F$40,J13,$E$2:$E$40) -> 0 | L13: 200 | M13: =L13-K13 -> 200
A14: 1 | B14: Louisy | D14: 5375 F/V P/B encadernação | E14: =215*25 -> 5375 | I14: ok | J14: 12 | K14: =SUMIF($F$2:$F$40,J14,$E$2:$E$40) -> 0 | L14: 100 | M14: =L14-K14 -> 100
A15: 19/20 | B15: Marcia | D15: 485 trofeus | I15: ok | J15: 13 | K15: =SUMIF($F$2:$F$40,J15,$E$2:$E$40) -> 0 | L15: 200 | M15: =L15-K15 -> 200
A16: 7 | B16: Jeniffer | C16: Frente color A4 | D16: Registro de Atividade | E16: =6*14 -> 84 | I16: ok | J16: 14 | K16: =SUMIF($F$2:$F$40,J16,$E$2:$E$40) -> 0 | L16: 200 | M16: =L16-K16 -> 200
A17: 7 | B17: Jeniffer | C17: Frente color A4 | D17: Roteiro para realização da atividade | E17: =30*1 -> 30 | I17: ok | J17: 15 | K17: =SUMIF($F$2:$F$40,J17,$E$2:$E$40) -> 0 | L17: 300 | M17: =L17-K17 -> 300
A18: 18 | B18: Jeniffer | D18: 6 impressões color, A4, 180 grs | E18: 6 | I18: ok | J18: 16 | K18: =SUMIF($F$2:$F$40,J18,$E$2:$E$40) -> 0 | L18: 200 | M18: =L18-K18 -> 200
A19: 13 | B19: Jeniffer | D19: 11 impressões color, A4, 180 grs | E19: 11 | I19: ok | J19: 17 | K19: =SUMIF($F$2:$F$40,J19,$E$2:$E$40) -> 0 | L19: 200 | M19: =L19-K19 -> 200
A20: 29 | B20: Amanda | C20: Pra começar | D20: A2 120 grs. Frente color | E20: =1*10 -> 10 | I20: ok | J20: 18 | K20: =SUMIF($F$2:$F$40,J20,$E$2:$E$40) -> 0 | L20: 500 | M20: =L20-K20 -> 500
A21: 28 | B21: Amanda | C21: Cognitivo | D21: A3 120 grs. Frente color | E21: =1*12 -> 12 | I21: ok | J21: 19 | K21: =SUMIF($F$2:$F$40,J21,$E$2:$E$40) -> 0 | L21: 80000 | M21: =L21-K21 -> 80000
A22: 28 | B22: Amanda | C22: Pedagogico | D22: A3 120 grs. Frente color | E22: =1*12 -> 12 | I22: ok | J22: 20 | K22: =SUMIF($F$2:$F$40,J22,$E$2:$E$40) -> 0 | L22: 500 | M22: =L22-K22 -> 500
A23: 28 | B23: Amanda | C23: Didatico | D23: A3 120 grs. Frente color | E23: =1*12 -> 12 | I23: ok | J23: 21 | K23: =SUMIF($F$2:$F$40,J23,$E$2:$E$40) -> 0 | L23: 50000 | M23: =L23-K23 -> 50000
B24: Pamela | D24: Situação 01 A4, frente, color | E24: =16*9 -> 144 | J24: 22 | K24: =SUMIF($F$2:$F$40,J24,$E$2:$E$40) -> 0 | L24: 500 | M24: =L24-K24 -> 500
B25: Pamela | D25: Situação 02 A4, frente, color | E25: =16*6 -> 96 | J25: 23 | K25: =SUMIF($F$2:$F$40,J25,$E$2:$E$40) -> 0 | L25: 80000 | M25: =L25-K25 -> 80000
B26: Pamela | D26: Situação 03 A4, frente, color | E26: =16*6 -> 96 | J26: 24 | K26: =SUMIF($F$2:$F$40,J26,$E$2:$E$40) -> 0 | L26: 500 | M26: =L26-K26 -> 500
B27: Pamela | D27: Situação 04 A4, frente, color | E27: =16*5 -> 80 | J27: 25 | K27: =SUMIF($F$2:$F$40,J27,$E$2:$E$40) -> 0 | L27: 50000 | M27: =L27-K27 -> 50000
A28: 24 | B28: Jeniffer | D28: Historia A4 P/B 120 grs | E28: =1*20 -> 20 | I28: ok | J28: 26 | K28: =SUMIF($F$2:$F$40,J28,$E$2:$E$40) -> 0 | L28: 300 | M28: =L28-K28 -> 300
A29: 24 | B29: Jeniffer | D29: Filo A4 P/B 120 grs | E29: =1*20 -> 20 | I29: ok | J29: 27 | K29: =SUMIF($F$2:$F$40,J29,$E$2:$E$40) -> 0 | L29: 300 | M29: =L29-K29 -> 300
A30: 24 | B30: Jeniffer | D30: Socio A4 P/B 120 grs | E30: =1*20 -> 20 | I30: ok | J30: 28 | K30: =SUMIF($F$2:$F$40,J30,$E$2:$E$40) -> 0 | L30: 300 | M30: =L30-K30 -> 300
A31: 23 | B31: Jeniffer | D31: Tabela 1 Historia A3 color 120 grs | E31: =1*10 -> 10 | I31: ok | J31: 29 | K31: =SUMIF($F$2:$F$40,J31,$E$2:$E$40) -> 0 | L31: 300 | M31: =L31-K31 -> 300
A32: 23 | B32: Jeniffer | D32: Tabela 1 Filo A3 color 120 grs | E32: =1*10 -> 10 | I32: ok | J32: 30 | K32: =SUMIF($F$2:$F$40,J32,$E$2:$E$40) -> 0 | L32: 300 | M32: =L32-K32 -> 300
A33: 23 | B33: Jeniffer | D33: Tabela 1 Socio A3 color 120 grs | E33: =1*10 -> 10 | I33: ok | J33: 31 | K33: =SUMIF($F$2:$F$40,J33,$E$2:$E$40) -> 0 | L33: 300 | M33: =L33-K33 -> 300
A34: 23 | B34: Jeniffer | D34: Tabela 2 Historia A3 color 120 grs | E34: =1*10 -> 10 | I34: ok | J34: 32 | K34: =SUMIF($F$2:$F$40,J34,$E$2:$E$40) -> 0 | L34: 300 | M34: =L34-K34 -> 300 | R34: =P34-Q34 -> 0
A35: 23 | B35: Jeniffer | D35: Tabela 1 Filo A3 color 120 grs | E35: =1*10 -> 10 | I35: ok | J35: 33 | K35: =SUMIF($F$2:$F$40,J35,$E$2:$E$40) -> 0 | L35: 200 | M35: =L35-K35 -> 200
A36: 23 | B36: Jeniffer | D36: Tabela 1 Socio A3 color 120 grs | E36: =1*10 -> 10 | I36: ok | J36: 34 | K36: =SUMIF($F$2:$F$40,J36,$E$2:$E$40) -> 0 | L36: 200 | M36: =L36-K36 -> 200 | R36: =P36-Q36 -> 0
A37: 12 | B37: Jeniffer | C37: Frente A4 Color | D37: Oficina Matematica | E37: =160*12 -> 1920 | I37: ok | J37: 35 | K37: =SUMIF($F$2:$F$40,J37,$E$2:$E$40) -> 0 | L37: 200 | M37: =L37-K37 -> 200 | R37: =P37-Q37 -> 0
A38: 6 | B38: Carol | D38: 07 Revistas | E38: 7 | I38: ok | J38: 36 | K38: =SUMIF($F$2:$F$40,J38,$E$2:$E$40) -> 0 | L38: 5000 | M38: =L38-K38 -> 5000 | R38: =P38-Q38 -> 0
B39: Jeniffer | C39: Tags | D39: 12 A4 180 grs | J39: 37 | K39: =SUMIF($F$2:$F$40,J39,$E$2:$E$40) -> 0 | L39: 300 | M39: =L39-K39 -> 300
A40: 14 | B40: Jeniffer | D40: Painel Coletivo A3 gram. Cartolina | E40: =40*2 -> 80 | I40: ok | J40: 38 | K40: =SUMIF($F$2:$F$40,J40,$E$2:$E$40) -> 0 | L40: 300 | M40: =L40-K40 -> 300
...

Sheet Abril
A1: Data | B1: Nome Solicitante | C1: Setor Responsável | D1: Pedido | E1: Quantidade | F1: Item | G1: Valor Unitário | H1: Valor do Pedido | J1: Controle de Utilização Mensal
A2: ok | B2: Isis | C2: Primeiros Passos | D2: 1000 Livretos color, A4, 75grs | E2: =1000*13 -> 13000 | G2: =IF(F2="","",VLOOKUP(F2,'Resumo Contrato Reajustado 2026'!$A$2:$S$43,18,0)) | H2: =IF(F2="","",E2*G2) | I2: 46118 | J2: Item | K2: Quantidade Utilizada | L2: Quantidade Mensal | M2: Total | O2: Valor a Pagar | P2: =SUM(H2:H48) -> 0
A3: ok | B3: Isis | C3: ESTAÇÃO1 | D3: 24 impressões color, A2, gramatura boa | E3: 24 | I3: 46118 | J3: 1 | K3: =SUMIF($F$2:$F$48,J3,$E$2:$E$48) -> 0 | L3: 5 | M3: =L3-K3 -> 5
A4: ok | B4: Isis | C4: ESTAÇÃO2 | D4: 24 impressões color, A2, gramatura boa | E4: 24 | I4: 46118 | J4: 2 | K4: =SUMIF($F$2:$F$48,J4,$E$2:$E$48) -> 0 | L4: 5 | M4: =L4-K4 -> 5
A5: ok | B5: Isis | C5: ESTAÇÃO3 | D5: 24 impressões color, A2, gramatura boa | E5: 24 | I5: 46118 | J5: 3 | K5: =SUMIF($F$2:$F$48,J5,$E$2:$E$48) -> 0 | L5: 5 | M5: =L5-K5 -> 5
A6: ok | B6: Isis | C6: ESTAÇÃO4 | D6: 24 impressões color, A2, gramatura boa | E6: 24 | I6: 46118 | J6: 4 | K6: =SUMIF($F$2:$F$48,J6,$E$2:$E$48) -> 0 | L6: 200 | M6: =L6-K6 -> 200
A7: ok | B7: Isis | C7: ESTAÇÃO5 | D7: 24 impressões color, A2, gramatura boa | E7: 24 | I7: 46118 | J7: 5 | K7: =SUMIF($F$2:$F$48,J7,$E$2:$E$48) -> 0 | L7: 200 | M7: =L7-K7 -> 200
A8: ok | B8: Isis | C8: ESTAÇÃO6 | D8: 24 impressões color, A2, gramatura boa | E8: 24 | I8: 46118 | J8: 6 | K8: =SUMIF($F$2:$F$48,J8,$E$2:$E$48) -> 0 | L8: 300 | M8: =L8-K8 -> 300
A9: ok | B9: Isis | C9: TEG PIRULITO | D9: 4 impressões color, gramatura boa, frente e verso | E9: 4 | I9: 46118 | J9: 7 | K9: =SUMIF($F$2:$F$48,J9,$E$2:$E$48) -> 0 | L9: 100 | M9: =L9-K9 -> 100
A10: ok | B10: Isis | C10: TERMOMÊTRO G | D10: 24 impressões color, gramatura boa | E10: 24 | I10: 46118 | J10: 8 | K10: =SUMIF($F$2:$F$48,J10,$E$2:$E$48) -> 0 | L10: 5 | M10: =L10-K10 -> 5
A11: ok | B11: Isis | C11: Avaliação SUP_PEC | D11: 130 impressões color, A4, 75grs | E11: 130 | I11: 46118 | J11: 9 | K11: =SUMIF($F$2:$F$48,J11,$E$2:$E$48) -> 0 | L11: 200 | M11: =L11-K11 -> 200
A12: ok | B12: Isis | C12: UMA CONVVERSA SOBRE DICIPLINA ESCOLAR | D12: 300 impressões color, A4, 75grs | E12: 300 | I12: 46118 | J12: 10 | K12: =SUMIF($F$2:$F$48,J12,$E$2:$E$48) -> 0 | L12: 200 | M12: =L12-K12 -> 200
A13: ok | B13: Isis | C13: Perspectivas de Vivências e Reflexões para o POC | D13: 800 impressões color, A4, 75grs, frente e verso | E13: =800*4 -> 3200 | I13: 46118 | J13: 11 | K13: =SUMIF($F$2:$F$48,J13,$E$2:$E$48) -> 0 | L13: 200 | M13: =L13-K13 -> 200
A14: ok | B14: Isis | C14: Avatar | D14: 130 color, cartão, só frente | E14: 130 | I14: 46118 | J14: 12 | K14: =SUMIF($F$2:$F$48,J14,$E$2:$E$48) -> 0 | L14: 100 | M14: =L14-K14 -> 100
A15: ok | B15: Isis | C15: Cartas | D15: 131 color, cartão, só frente | E15: 130 | I15: 46118 | J15: 13 | K15: =SUMIF($F$2:$F$48,J15,$E$2:$E$48) -> 0 | L15: 200 | M15: =L15-K15 -> 200
A16: ok | B16: Isis | C16: Coração | D16: 800 impressões color, A4, 90 grs | E16: 800 | I16: 46118 | J16: 14 | K16: =SUMIF($F$2:$F$48,J16,$E$2:$E$48) -> 0 | L16: 200 | M16: =L16-K16 -> 200
A17: ok | B17: Isis | C17: Fluxograma | D17: 800 impressões color, frente e verso, 75grs | E17: =800*2 -> 1600 | I17: 46118 | J17: 15 | K17: =SUMIF($F$2:$F$48,J17,$E$2:$E$48) -> 0 | L17: 300 | M17: =L17-K17 -> 300
A18: ok | B18: Isis | C18: Tabuleiro - Rota da Prevenção | D18: 130 impressões color, A2, gramatura boa | E18: 130 | I18: 46118 | J18: 16 | K18: =SUMIF($F$2:$F$48,J18,$E$2:$E$48) -> 0 | L18: 200 | M18: =L18-K18 -> 200
A19: ok | B19: Isis | C19: Jogo Oficina - Convivência | D19: 103 cartões color, frente e verso | E19: 103 | I19: 46118 | J19: 17 | K19: =SUMIF($F$2:$F$48,J19,$E$2:$E$48) -> 0 | L19: 200 | M19: =L19-K19 -> 200
A20: ok | B20: Isis | C20: Tabuleiro - Rota da Convivencia | D20: 103 impressões color, A2, gramatura boa | E20: 103 | I20: 46118 | J20: 18 | K20: =SUMIF($F$2:$F$48,J20,$E$2:$E$48) -> 0 | L20: 500 | M20: =L20-K20 -> 500
A21: ok | B21: Isis | C21: Cartas | D21: 20 impressõe color, A4, cartão | E21: 20 | I21: 46118 | J21: 19 | K21: =SUMIF($F$2:$F$48,J21,$E$2:$E$48) -> 0 | L21: 80000 | M21: =L21-K21 -> 80000
A22: ok | B22: Isis | C22: Regras Jogo da Convivência | D22: 103 impressões color, A5, frente e verso, 90 grs | E22: 103 | I22: 46118 | J22: 20 | K22: =SUMIF($F$2:$F$48,J22,$E$2:$E$48) -> 0 | L22: 500 | M22: =L22-K22 -> 500
A23: ok | B23: Isis | C23: Escudo da Prevenção | D23: 800 impressões color, A4, 90 grs | E23: 800 | I23: 46118 | J23: 21 | K23: =SUMIF($F$2:$F$48,J23,$E$2:$E$48) -> 0 | L23: 50000 | M23: =L23-K23 -> 50000
A24: ok | B24: Isis | C24: TERMOMÊTRO G | D24: 76 impressões color, A2, gramatura boa | E24: 76 | I24: 46118 | J24: 22 | K24: =SUMIF($F$2:$F$48,J24,$E$2:$E$48) -> 0 | L24: 500 | M24: =L24-K24 -> 500
A25: ok | B25: Isis | C25: Fluxograma de Prevenção | D25: 250 impressões color, A4, sulfite | E25: 250 | I25: 46118 | J25: 23 | K25: =SUMIF($F$2:$F$48,J25,$E$2:$E$48) -> 0 | L25: 80000 | M25: =L25-K25 -> 80000
A26: ok | B26: Isis | C26: Planta Baixa | D26: 130 impressões pb, A2, 75grs | E26: 130 | I26: 46118 | J26: 24 | K26: =SUMIF($F$2:$F$48,J26,$E$2:$E$48) -> 0 | L26: 500 | M26: =L26-K26 -> 500
A27: ok | B27: Isis | C27: Situação de Conflito Cartas | D27: 103 impressões color, cartao, A4, frente e verso | E27: 103 | I27: 46118 | J27: 25 | K27: =SUMIF($F$2:$F$48,J27,$E$2:$E$48) -> 0 | L27: 50000 | M27: =L27-K27 -> 50000
A28: ok | B28: Isis | C28: Situação de Conflito | D28: 103 impressões color, A2, 75grs | E28: 103 | I28: 46118 | K28: =SUMIF($F$2:$F$48,#REF!,$E$2:$E$48) -> 0 | L28: 300 | M28: =L28-K28 -> 300
A29: ok | B29: Isis | C29: FLYER_EVENTO_CONVIVA_PEC | D29: 250 flyers color, A5, frente e verso | E29: 250 | I29: 46118 | J29: 27 | K29: =SUMIF($F$2:$F$48,J29,$E$2:$E$48) -> 0 | L29: 300 | M29: =L29-K29 -> 300
A30: ok | B30: Isis | C30: FLYER_EVENTO_CONVIVA_POC | D30: 750 flyers, color, A5, frente e verso | E30: 750 | I30: 46118 | J30: 28 | K30: =SUMIF($F$2:$F$48,J30,$E$2:$E$48) -> 0 | L30: 300 | M30: =L30-K30 -> 300
A31: ok | B31: Isis | C31: Estudo de caso | D31: 800 impressões color, A4, 75grs, frente e verso | E31: 800 | I31: 46118 | J31: 29 | K31: =SUMIF($F$2:$F$48,J31,$E$2:$E$48) -> 0 | L31: 300 | M31: =L31-K31 -> 300
A32: ok | B32: Warley/Marcia | C32: premiação encontro de líderes | D32: 300 canudos brancos e 300 canudos amarelos | E32: =2*300 -> 600 | I32: 46112 | J32: 30 | K32: =SUMIF($F$2:$F$48,J32,$E$2:$E$48) -> 0 | L32: 300 | M32: =L32-K32 -> 300
A33: ok | B33: Warley/Giovanna | C33: cartões de acesso cultural | D33: 179 cartões color, 19cmx7cm, papel brilhante, 180grs frente e verso | E33: 179 | I33: 46113 | J33: 31 | K33: =SUMIF($F$2:$F$48,J33,$E$2:$E$48) -> 0 | L33: 300 | M33: =L33-K33 -> 300
A34: ok | B34: Warley/Marcia | C34: Crendenciais | D34: 1520 impressões, color, 09cmx15cm, couche, 300grs | E34: 1520 | I34: 46114 | J34: 32 | K34: =SUMIF($F$2:$F$48,J34,$E$2:$E$48) -> 0 | L34: 300 | M34: =L34-K34 -> 300 | R34: =P34-Q34 -> 0
B35: Fatima | C35: Certificado | D35: 1 impressão color, A4, papel brilhante ou semelhante, 180 grs só frente | E35: 1 | I35: 46114 | J35: 33 | K35: =SUMIF($F$2:$F$48,J35,$E$2:$E$48) -> 0 | L35: 200 | M35: =L35-K35 -> 200
A36: ok | B36: Warley /Andre | C36: Folder DICON | D36: 7 impressões color, A4, papel couche, frente e verso | E36: 7 | I36: 46114 | J36: 34 | K36: =SUMIF($F$2:$F$48,J36,$E$2:$E$48) -> 0 | L36: 200 | M36: =L36-K36 -> 200 | R36: =P36-Q36 -> 0
A37: ok | B37: Warley | C37: Adesivo guarda-chuva | D37: 11 impressoes pb, A4, papel adesivo, so frente | E37: 11 | I37: 46122 | J37: 35 | K37: =SUMIF($F$2:$F$48,J37,$E$2:$E$48) -> 0 | L37: 200 | M37: =L37-K37 -> 200 | R37: =P37-Q37 -> 0
A38: ok | B38: Jennifer | C38: Quadro de Evidencias | D38: 1100 impressões color, A4, sulfite, só frente | E38: 1100 | I38: 46119 | J38: 36 | K38: =SUMIF($F$2:$F$48,J38,$E$2:$E$48) -> 0 | L38: 5000 | M38: =L38-K38 -> 5000 | R38: =P38-Q38 -> 0
A39: ok | B39: Jennifer | C39: Protocolo de Observação | D39: 1100 impressões pb, A4, sulfite, frente e verso | E39: 1100 | I39: 46119 | J39: 37 | K39: =SUMIF($F$2:$F$48,J39,$E$2:$E$48) -> 0 | L39: 300 | M39: =L39-K39 -> 300
B40: Milene | C40: Cartão de visita | D40: 01 cento Cartão de visita F/V | E40: 100 | J40: 38 | K40: =SUMIF($F$2:$F$48,J40,$E$2:$E$48) -> 0 | L40: 300 | M40: =L40-K40 -> 300
...

Sheet Maio
A1: Data | B1: Nome Solicitante | C1: Setor Responsável | D1: Pedido | E1: Quantidade | F1: Item | G1: Valor Unitário | H1: Valor do Pedido | J1: Controle de Utilização Mensal
G2: =IF(F2="","",VLOOKUP(F2,'Resumo Contrato Reajustado 2026'!$A$2:$S$43,18,0)) | H2: =IF(F2="","",E2*G2) | J2: Item | K2: Quantidade Utilizada | L2: Quantidade Mensal | M2: Total | O2: Valor a Pagar | P2: =SUM(H2:H46) -> 0
G3: =IF(F3="","",VLOOKUP(F3,'Resumo Contrato Reajustado 2026'!$A$2:$S$43,18,0)) | H3: =IF(F3="","",E3*G3) | J3: 1 | K3: =SUMIF($F$2:$F$46,J3,$E$2:$E$46) -> 0 | L3: 5 | M3: =L3-K3 -> 5
J4: 2 | K4: =SUMIF($F$2:$F$46,J4,$E$2:$E$46) -> 0 | L4: 5 | M4: =L4-K4 -> 5
J5: 3 | K5: =SUMIF($F$2:$F$46,J5,$E$2:$E$46) -> 0 | L5: 5 | M5: =L5-K5 -> 5
J6: 4 | K6: =SUMIF($F$2:$F$46,J6,$E$2:$E$46) -> 0 | L6: 200 | M6: =L6-K6 -> 200
J7: 5 | K7: =SUMIF($F$2:$F$46,J7,$E$2:$E$46) -> 0 | L7: 200 | M7: =L7-K7 -> 200
J8: 6 | K8: =SUMIF($F$2:$F$46,J8,$E$2:$E$46) -> 0 | L8: 300 | M8: =L8-K8 -> 300
J9: 7 | K9: =SUMIF($F$2:$F$46,J9,$E$2:$E$46) -> 0 | L9: 100 | M9: =L9-K9 -> 100
J10: 8 | K10: =SUMIF($F$2:$F$46,J10,$E$2:$E$46) -> 0 | L10: 5 | M10: =L10-K10 -> 5
J11: 9 | K11: =SUMIF($F$2:$F$46,J11,$E$2:$E$46) -> 0 | L11: 200 | M11: =L11-K11 -> 200
J12: 10 | K12: =SUMIF($F$2:$F$46,J12,$E$2:$E$46) -> 0 | L12: 200 | M12: =L12-K12 -> 200
J13: 11 | K13: =SUMIF($F$2:$F$46,J13,$E$2:$E$46) -> 0 | L13: 200 | M13: =L13-K13 -> 200
J14: 12 | K14: =SUMIF($F$2:$F$46,J14,$E$2:$E$46) -> 0 | L14: 100 | M14: =L14-K14 -> 100
J15: 13 | K15: =SUMIF($F$2:$F$46,J15,$E$2:$E$46) -> 0 | L15: 200 | M15: =L15-K15 -> 200
... J33: 31 | K33: =SUMIF($F$2:$F$46,J33,$E$2:$E$46) -> 0 | L33: 300 | M33: =L33-K33 -> 300
J34: 32 | K34: =SUMIF($F$2:$F$46,J34,$E$2:$E$46) -> 0 | L34: 300 | M34: =L34-K34 -> 300 | R34: =P34-Q34 -> 0
J35: 33 | K35: =SUMIF($F$2:$F$46,J35,$E$2:$E$46) -> 0 | L35: 200 | M35: =L35-K35 -> 200
J36: 34 | K36: =SUMIF($F$2:$F$46,J36,$E$2:$E$46) -> 0 | L36: 200 | M36: =L36-K36 -> 200 | R36: =P36-Q36 -> 0
J37: 35 | K37: =SUMIF($F$2:$F$46,J37,$E$2:$E$46) -> 0 | L37: 200 | M37: =L37-K37 -> 200 | R37: =P37-Q37 -> 0
J38: 36 | K38: =SUMIF($F$2:$F$46,J38,$E$2:$E$46) -> 0 | L38: 5000 | M38: =L38-K38 -> 5000 | R38: =P38-Q38 -> 0
J39: 37 | K39: =SUMIF($F$2:$F$46,J39,$E$2:$E$46) -> 0 | L39: 300 | M39: =L39-K39 -> 300
J40: 38 | K40: =SUMIF($F$2:$F$46,J40,$E$2:$E$46) -> 0 | L40: 300 | M40: =L40-K40 -> 300
J41: 39 | K41: =SUMIF($F$2:$F$46,J41,$E$2:$E$46) -> 0 | L41: 30 | M41: =L41-K41 -> 30
J42: 40 | K42: =SUMIF($F$2:$F$46,J42,$E$2:$E$46) -> 0 | L42: 30 | M42: =L42-K42 -> 30
J43: 41 | K43: =SUMIF($F$2:$F$46,J43,$E$2:$E$46) -> 0 | L43: 30 | M43: =L43-K43 -> 30
J44: 42 | K44: =SUMIF($F$2:$F$46,J44,$E$2:$E$46) -> 0 | L44: 30 | M44: =L44-K44 -> 30

Sheet Junho
A1: Data | B1: Nome Solicitante | C1: Setor Responsável | D1: Pedido | E1: Quantidade | F1: Item | G1: Valor Unitário | H1: Valor do Pedido | J1: Controle de Utilização Mensal
E2: 5525 | F2: 25 | G2: =IF(F2="","",VLOOKUP(F2,'Resumo Contrato Reajustado 2026'!$A$2:$S$43,18,0)) -> 0.85490906 | H2: =IF(F2="","",E2*G2) -> 4723.3725 | J2: Item | K2: Quantidade Utilizada | L2: Quantidade Mensal | M2: Total | O2: Valor a Pagar | P2: =SUM(H2:H46) -> 4723.3725
G3: =IF(F3="","",VLOOKUP(F3,'Resumo Contrato Reajustado 2026'!$A$2:$S$43,18,0)) | H3: =IF(F3="","",E3*G3) | J3: 1 | K3: =SUMIF($F$2:$F$46,J3,$E$2:$E$46) -> 0 | L3: 5 | M3: =L3-K3 -> 5
J4: 2 | K4: =SUMIF($F$2:$F$46,J4,$E$2:$E$46) -> 0 | L4: 5 | M4: =L4-K4 -> 5
J5: 3 | K5: =SUMIF($F$2:$F$46,J5,$E$2:$E$46) -> 0 | L5: 5 | M5: =L5-K5 -> 5
J6: 4 | K6: =SUMIF($F$2:$F$46,J6,$E$2:$E$46) -> 0 | L6: 200 | M6: =L6-K6 -> 200
J7: 5 | K7: =SUMIF($F$2:$F$46,J7,$E$2:$E$46) -> 0 | L7: 200 | M7: =L7-K7 -> 200
J8: 6 | K8: =SUMIF($F$2:$F$46,J8,$E$2:$E$46) -> 0 | L8: 300 | M8: =L8-K8 -> 300
J9: 7 | K9: =SUMIF($F$2:$F$46,J9,$E$2:$E$46) -> 0 | L9: 100 | M9: =L9-K9 -> 100
J10: 8 | K10: =SUMIF($F$2:$F$46,J10,$E$2:$E$46) -> 0 | L10: 5 | M10: =L10-K10 -> 5
J11: 9 | K11: =SUMIF($F$2:$F$46,J11,$E$2:$E$46) -> 0 | L11: 200 | M11: =L11-K11 -> 200
J12: 10 | K12: =SUMIF($F$2:$F$46,J12,$E$2:$E$46) -> 0 | L12: 200 | M12: =L12-K12 -> 200
J13: 11 | K13: =SUMIF($F$2:$F$46,J13,$E$2:$E$46) -> 0 | L13: 200 | M13: =L13-K13 -> 200
J14: 12 | K14: =SUMIF($F$2:$F$46,J14,$E$2:$E$46) -> 0 | L14: 100 | M14: =L14-K14 -> 100
J15: 13 | K15: =SUMIF($F$2:$F$46,J15,$E$2:$E$46) -> 0 | L15: 200 | M15: =L15-K15 -> 200
... J33: 31 | K33: =SUMIF($F$2:$F$46,J33,$E$2:$E$46) -> 0 | L33: 300 | M33: =L33-K33 -> 300
J34: 32 | K34: =SUMIF($F$2:$F$46,J34,$E$2:$E$46) -> 0 | L34: 300 | M34: =L34-K34 -> 300 | R34: =P34-Q34 -> 0
J35: 33 | K35: =SUMIF($F$2:$F$46,J35,$E$2:$E$46) -> 0 | L35: 200 | M35: =L35-K35 -> 200
J36: 34 | K36: =SUMIF($F$2:$F$46,J36,$E$2:$E$46) -> 0 | L36: 200 | M36: =L36-K36 -> 200 | R36: =P36-Q36 -> 0
J37: 35 | K37: =SUMIF($F$2:$F$46,J37,$E$2:$E$46) -> 0 | L37: 200 | M37: =L37-K37 -> 200 | R37: =P37-Q37 -> 0
J38: 36 | K38: =SUMIF($F$2:$F$46,J38,$E$2:$E$46) -> 0 | L38: 5000 | M38: =L38-K38 -> 5000 | R38: =P38-Q38 -> 0
J39: 37 | K39: =SUMIF($F$2:$F$46,J39,$E$2:$E$46) -> 0 | L39: 300 | M39: =L39-K39 -> 300
J40: 38 | K40: =SUMIF($F$2:$F$46,J40,$E$2:$E$46) -> 0 | L40: 300 | M40: =L40-K40 -> 300
J41: 39 | K41: =SUMIF($F$2:$F$46,J41,$E$2:$E$46) -> 0 | L41: 30 | M41: =L41-K41 -> 30
J42: 40 | K42: =SUMIF($F$2:$F$46,J42,$E$2:$E$46) -> 0 | L42: 30 | M42: =L42-K42 -> 30
J43: 41 | K43: =SUMIF($F$2:$F$46,J43,$E$2:$E$46) -> 0 | L43: 30 | M43: =L43-K43 -> 30
J44: 42 | K44: =SUMIF($F$2:$F$46,J44,$E$2:$E$46) -> 0 | L44: 30 | M44: =L44-K44 -> 30

Sheet Consolidação
A1: Cód. Item | B1: Item Contratual | C1: Valor do Item | D1: Indice Reajuste | E1: Valor Reajustado | F1: Indice Reajuste | G1: Valor Reajustado | H1: Indice Reajuste | I1: Valor Reajustado | J1: Indice Reajuste | K1: Valor Reajustado | L1: Quantidade Contratada | M1: Quantidade Empenhada | N1: Quantidade Utilizada | O1: Saldo a Utilizar | P1: Valor Empenhado | Q1: Valor Utilizado | R1: Saldo a utilizar | S1: 0
A2: 1 | B2: Banner - Banner em lona com impressão digital de alta qualidade, medida 1,20m x 0,90m acabamento de madeira e ponta de PVC, com tripé. | C2: 75 | D2: 0.082 | E2: =C2+C2*D2 -> 81.15 | F2: 0.0351 | G2: =E2+E2*F2 -> 83.998365 | H2: 0.0345 | I2: =G2+G2*H2 -> 86.896309 | J2: 0.0541 | K2: =I2+I2*J2 -> 91.597399 | L2: 5 | M2: =L2*$S$1 -> 0 | N2: =SUM(Janeiro:Março!K3) -> 0 | O2: =M2-N2 -> 0 | P2: =K2*M2 -> 0 | Q2: =N2*K2 -> 0 | R2: =P2-Q2 -> 0
A3: 2 | B3: Banner - Banner em lona com impressão digital de alta qualidade, medida 1,50m x 0,90m acabamento de madeira e ponta de PVC, com tripé. | C3: 85 | D3: 0.082 | E3: =C3+C3*D3 -> 91.97 | F3: 0.0351 | G3: =E3+E3*F3 -> 95.198147 | H3: 0.0345 | I3: =G3+G3*H3 -> 98.482483 | J3: 0.0541 | K3: =I3+I3*J3 -> 103.81039 | L3: 5 | M3: =L3*$S$1 -> 0 | N3: =SUM(Janeiro:Março!K4) -> 5 | O3: =M3-N3 -> -5 | P3: =K3*M3 -> 0 | Q3: =N3*K3 -> 519.05193 | R3: =P3-Q3 -> -519.05193
A4: 3 | B4: Banner- Banner em lona com impressão digital de alta qualidade, medida 1,30X 1,80m acabamento de madeira e ponta de PVC, com tripé. | C4: 120 | D4: 0.082 | E4: =C4+C4*D4 -> 129.84 | F4: 0.0351 | G4: =E4+E4*F4 -> 134.39738 | H4: 0.0345 | I4: =G4+G4*H4 -> 139.03409 | J4: 0.0541 | K4: =I4+I4*J4 -> 146.55584 | L4: 5 | M4: =L4*$S$1 -> 0 | N4: =SUM(Janeiro:Março!K5) -> 0 | O4: =M4-N4 -> 0 | P4: =K4*M4 -> 0 | Q4: =N4*K4 -> 0 | R4: =P4-Q4 -> 0
A5: 4 | B5: Cartão Cerimonial - Cartão cerimonial formato 12,5cm x 8,5cm, papel cartão supremo 330gr impressão 1 x 1 cores | C5: 0.9 | D5: 0.082 | E5: =C5+C5*D5 -> 0.9738 | F5: 0.0351 | G5: =E5+E5*F5 -> 1.0079804 | H5: 0.0345 | I5: =G5+G5*H5 -> 1.0427557 | J5: 0.0541 | K5: =I5+I5*J5 -> 1.0991688 | L5: 200 | M5: =L5*$S$1 -> 0 | N5: =SUM(Janeiro:Março!K6) -> 358 | O5: =M5-N5 -> -358 | P5: =K5*M5 -> 0 | Q5: =N5*K5 -> 393.50243 | R5: =P5-Q5 -> -393.50243
A6: 5 | B6: Cartão Cerimonial -Cartão cerimonial formato 12,5cm x 8,5cm, papel cartão supremo 330gr impressão 4 x 0 cores | C6: 0.9 | D6: 0.082 | E6: =C6+C6*D6 -> 0.9738 | F6: 0.0351 | G6: =E6+E6*F6 -> 1.0079804 | H6: 0.0345 | I6: =G6+G6*H6 -> 1.0427557 | J6: 0.0541 | K6: =I6+I6*J6 -> 1.0991688 | L6: 200 | M6: =L6*$S$1 -> 0 | N6: =SUM(Janeiro:Março!K7) -> 166 | O6: =M6-N6 -> -166 | P6: =K6*M6 -> 0 | Q6: =N6*K6 -> 182.46202 | R6: =P6-Q6 -> -182.46202
A7: 6 | B7: Cartão de visita - Cartão de visita formato 9,5cm x 5,5cm, acabamento refile. | C7: 0.12 | D7: 0.082 | E7: =C7+C7*D7 -> 0.12984 | F7: 0.0351 | G7: =E7+E7*F7 -> 0.13439738 | H7: 0.0345 | I7: =G7+G7*H7 -> 0.13903409 | J7: 0.0541 | K7: =I7+I7*J7 -> 0.14655584 | L7: 300 | M7: =L7*$S$1 -> 0 | N7: =SUM(Janeiro:Março!K8) -> 0 | O7: =M7-N7 -> 0 | P7: =K7*M7 -> 0 | Q7: =N7*K7 -> 0 | R7: =P7-Q7 -> 0
A8: 7 | B8: Cartão de visita - EM BRAILEARTE/MATRIZES ,TRADUÇÃO E REVISÃO ORTOGRÁFICA EM BRAILE POR CONTA DA CONTRATADA Cartão de 9,5cm(L) x 5,5cm(A); papel duplex 300gr ou cartão, impressão 4X0 cores, gravação braile na frente. | C8: 2 | D8: 0.082 | E8: =C8+C8*D8 -> 2.164 | F8: 0.0351 | G8: =E8+E8*F8 -> 2.2399564 | H8: 0.0345 | I8: =G8+G8*H8 -> 2.3172349 | J8: 0.0541 | K8: =I8+I8*J8 -> 2.4425973 | L8: 100 | M8: =L8*$S$1 -> 0 | N8: =SUM(Janeiro:Março!K9) -> 0 | O8: =M8-N8 -> 0 | P8: =K8*M8 -> 0 | Q8: =N8*K8 -> 0 | R8: =P8-Q8 -> 0
A9: 8 | B9: Cartaz -Cartaz formato 60cm x 40cm, papel couche 150gr, impressão 4 x 0 cores, acabamento dupla face e refile | C9: 12 | D9: 0.082 | E9: =C9+C9*D9 -> 12.984 | F9: 0.0351 | G9: =E9+E9*F9 -> 13.439738 | H9: 0.0345 | I9: =G9+G9*H9 -> 13.903409 | J9: 0.0541 | K9: =I9+I9*J9 -> 14.655584 | L9: 5 | M9: =L9*$S$1 -> 0 | N9: =SUM(Janeiro:Março!K10) -> 0 | O9: =M9-N9 -> 0 | P9: =K9*M9 -> 0 | Q9: =N9*K9 -> 0 | R9: =P9-Q9 -> 0
A10: 9 | B10: Cartilha- Cartilha formato 29,7cm x 21cm, A4 fechado, 96 páginas, papel couche 115gr, impressão 4 x 4 cores, acabamento hotmelt | C10: 14 | D10: 0.082 | E10: =C10+C10*D10 -> 15.148 | F10: 0.0351 | G10: =E10+E10*F10 -> 15.679695 | H10: 0.0345 | I10: =G10+G10*H10 -> 16.220644 | J10: 0.0541 | K10: =I10+I10*J10 -> 17.098181 | L10: 200 | M10: =L10*$S$1 -> 0 | N10: =SUM(Janeiro:Março!K11) -> 126 | O10: =M10-N10 -> -126 | P10: =K10*M10 -> 0 | Q10: =N10*K10 -> 2154.3708 | R10: =P10-Q10 -> -2154.3708
A11: 10 | B11: Cartilha/ book -Cartilha formato 29,7cm x 21cm, 96 páginas, papel couche 115gr, impressão 4 x 4 cores, capa dura | C11: 16 | D11: 0.082 | E11: =C11+C11*D11 -> 17.312 | F11: 0.0351 | G11: =E11+E11*F11 -> 17.919651 | H11: 0.0345 | I11: =G11+G11*H11 -> 18.537879 | J11: 0.0541 | K11: =I11+I11*J11 -> 19.540778 | L11: 200 | M11: =L11*$S$1 -> 0 | N11: =SUM(Janeiro:Março!K12) -> 0 | O11: =M11-N11 -> 0 | P11: =K11*M11 -> 0 | Q11: =N11*K11 -> 0 | R11: =P11-Q11 -> 0
A12: 11 | B12: Certificado - Certificado formato 21cm x 29,7 - A4, papel couche brilho 300gr, impressão 4 x 0 cores, acabamento refile | C12: 0.9 | D12: 0.082 | E12: =C12+C12*D12 -> 0.9738 | F12: 0.0351 | G12: =E12+E12*F12 -> 1.0079804 | H12: 0.0345 | I12: =G12+G12*H12 -> 1.0427557 | J12: 0.0541 | K12: =I12+I12*J12 -> 1.0991688 | L12: 200 | M12: =L12*$S$1 -> 0 | N12: =SUM(Janeiro:Março!K13) -> 241 | O12: =M12-N12 -> -241 | P12: =K12*M12 -> 0 | Q12: =N12*K12 -> 264.89968 | R12: =P12-Q12 -> -264.89968
A13: 12 | B13: Convite - Convite formato 17cm x 9cm, papel couche brilho 170gr, numerado impressão 4 x 0 cores, acabamento refile | C13: 1.39 | D13: 0.082 | E13: =C13+C13*D13 -> 1.50398 | F13: 0.0351 | G13: =E13+E13*F13 -> 1.5567697 | H13: 0.0345 | I13: =G13+G13*H13 -> 1.6104783 | J13: 0.0541 | K13: =I13+I13*J13 -> 1.6976051 | L13: 100 | M13: =L13*$S$1 -> 0 | N13: =SUM(Janeiro:Março!K14) -> 0 | O13: =M13-N13 -> 0 | P13: =K13*M13 -> 0 | Q13: =N13*K13 -> 0 | R13: =P13-Q13 -> 0
... A43: 42 | B43: Serviço de impressão/plotagem colorida de Projetos de Engenharia incluso dobragem conforme ABNT/NBR 13142/1999, formatos série ABNT A2. Impressão a laser ou tinta térmica em papel sulfite branco, gramatura mínima 75g/m2, resolução de impressão igual ou superior a 1200dpi x 1200 dpi (ponto por polegada quadrada), a partir de arquivos digitais a serem fornecidos pela CONTRATANTE | C43: 7.88 | D43: 0.082 | E43: =C43+C43*D43 -> 8.52616 | F43: 0.0351 | G43: =E43+E43*F43 -> 8.8254282 | H43: 0.0345 | I43: =G43+G43*H43 -> 9.1299055 | J43: 0.0541 | K43: =I43+I43*J43 -> 9.6238334 | L43: 30 | M43: =L43*$S$1 -> 0 | N43: =SUM(Janeiro:Março!K44) -> 0 | O43: =M43-N43 -> 0 | P43: =K43*M43 -> 0 | Q43: =N43*K43 -> 0 | R43: =P43-Q43 -> 0
